<?xml version="1.0" encoding="utf-8"?>
<!-- =================================================================================== -->
<!-- |    This document was autogenerated by xacro from roomba.xacro                   | -->
<!-- |    EDITING THIS FILE BY HAND IS NOT RECOMMENDED                                 | -->
<!-- =================================================================================== -->
<!-- iRobot Roomba 650 model -->
<robot name="roomba" xmlns:xacro="http://www.ros.org/wiki/xacro">
  <material name="black">
    <color rgba="0.0 0.0 0.0 1.0"/>
  </material>
  <material name="blue">
    <color rgba="0.0 0.0 0.8 1.0"/>
  </material>
  <material name="green">
    <color rgba="0.0 0.8 0.0 1.0"/>
  </material>
  <material name="green_transparent">
    <color rgba="0.0 0.8 0.0 0.75"/>
  </material>
  <material name="grey">
    <color rgba="0.2 0.2 0.2 1.0"/>
  </material>
  <material name="orange">
    <color rgba="1.0 0.423529411765 0.0392156862745 1.0"/>
  </material>
  <material name="orange_transparent">
    <color rgba="1.0 0.423529411765 0.0392156862745 0.75"/>
  </material>
  <material name="brown">
    <color rgba="0.870588235294 0.811764705882 0.764705882353 1.0"/>
  </material>
  <material name="red">
    <color rgba="0.8 0.0 0.0 1.0"/>
  </material>
  <material name="white">
    <color rgba="1.0 1.0 1.0 1.0"/>
  </material>
  <!-- <link name="world"/>

  <joint name="world_base" type="fixed">
    <origin xyz="0 0 ${base_zgap+base_height/2}" rpy="0 0 0"/>
    <parent link="world"/>
    <child link="base"/>
  </joint> -->
  <link name="base">
    <inertial>
      <origin rpy="0 0 0" xyz="0 0 0"/>
      <mass value="3.0"/>
      <inertia ixx="0.045414" ixy="0.0" ixz="0.0" iyy="0.02967925" iyz="0.0" izz="0.02967925"/>
    </inertial>
    <visual>
      <origin rpy="0 0 0" xyz="0 0 0"/>
      <geometry>
        <cylinder length="-0.167" radius="0.174"/>
      </geometry>
      <material name="green_transparent"/>
    </visual>
    <collision>
      <origin rpy="0 0 0" xyz="0 0 0"/>
      <geometry>
        <cylinder length="-0.167" radius="0.174"/>
      </geometry>
    </collision>
  </link>
  <gazebo reference="base">
    <material>Gazebo/Green</material>
    <pose>0 0 3 0 0 0</pose>
  </gazebo>
  <joint name="roller_joint" type="fixed">
    <origin rpy="0 0 0" xyz="0.135 0 0.0835"/>
    <parent link="base"/>
    <child link="roller"/>
  </joint>
  <link name="roller">
    <inertial>
      <origin rpy="0 0 0" xyz="0 0 0"/>
      <mass value="0.05"/>
      <inertia ixx="0.00125" ixy="0.0" ixz="0.0" iyy="0.00125" iyz="0.0" izz="0.00125"/>
    </inertial>
    <visual>
      <origin rpy="0 0 0" xyz="0 0 0"/>
      <geometry>
        <sphere radius="0.25"/>
      </geometry>
      <material name="green_transparent"/>
    </visual>
    <collision>
      <origin rpy="0 0 0" xyz="0 0 0"/>
      <geometry>
        <sphere radius="0.25"/>
      </geometry>
    </collision>
  </link>
  <gazebo reference="roller">
    <material>Gazebo/Green</material>
  </gazebo>
  <link name="right_wheel">
    <inertial>
      <origin rpy="0 0 0" xyz="0 0 0"/>
      <mass value="0.01"/>
      <inertia ixx="0.001" ixy="0.0" ixz="0.0" iyy="0.001" iyz="0.0" izz="0.001"/>
    </inertial>
    <visual>
      <origin rpy="0 0 0" xyz="0 0 0"/>
      <geometry>
        <cylinder length="0.015" radius="0.036"/>
      </geometry>
      <material name="black"/>
    </visual>
    <collision>
      <origin rpy="0 0 0" xyz="0 0 0"/>
      <geometry>
        <cylinder length="0.015" radius="0.036"/>
      </geometry>
    </collision>
  </link>
  <gazebo reference="right_wheel">
    <material>Gazebo/Black</material>
  </gazebo>
  <joint name="right_wheel_joint" type="continuous">
    <origin rpy="-1.570796 0 0" xyz="-0.04 0.1175 -0.1305"/>
    <axis xyz="0 0 1"/>
    <parent link="base"/>
    <child link="right_wheel"/>
    <dynamics damping="0.5"/>
  </joint>
  <link name="left_wheel">
    <inertial>
      <origin rpy="0 0 0" xyz="0 0 0"/>
      <mass value="0.01"/>
      <inertia ixx="0.001" ixy="0.0" ixz="0.0" iyy="0.001" iyz="0.0" izz="0.001"/>
    </inertial>
    <visual>
      <origin rpy="0 0 0" xyz="0 0 0"/>
      <geometry>
        <cylinder length="0.015" radius="0.036"/>
      </geometry>
      <material name="black"/>
    </visual>
    <collision>
      <origin rpy="0 0 0" xyz="0 0 0"/>
      <geometry>
        <cylinder length="0.015" radius="0.036"/>
      </geometry>
    </collision>
  </link>
  <gazebo reference="left_wheel">
    <material>Gazebo/Black</material>
  </gazebo>
  <joint name="left_wheel_joint" type="continuous">
    <origin rpy="-1.570796 0 0" xyz="-0.04 -0.1175 -0.1305"/>
    <axis xyz="0 0 1"/>
    <parent link="base"/>
    <child link="left_wheel"/>
    <dynamics damping="0.5"/>
  </joint>
</robot>

